Workbook

Sheet README
A1: Tokenised equities mock ledger (Excel version)
A2: An illustrative model of the accounting and reconciliation for an issuer of tokens backed 1:1 by listed shares. Synthetic data. Not any real company's model.
A4: Purpose | B4: Show how issuance, redemption, hedging and fair value flow through a ledger, and how a three-way reconciliation (on-chain vs ledger vs custodian) and transaction-level tests find breaks.
A5: Colour legend | B5: Blue text = typed input. Black text = formula. Yellow fill = key assumption. Green/amber/red = test result.
A6: Tabs | B6: Assumptions (fee, report date, prices) | COA | OnChain | Custodian | Journal | TrialBalance | Recon | Tests | Findings
A7: How the numbers flow | B7: OnChain and Custodian are source records. Journal holds the ledger, with amounts calculated from quantity and price. TrialBalance, Recon and Tests are all formulas over those tabs.
A8: Policy assumptions | B8: Tokens are financial liabilities at FVTPL; backing shares are financial assets at FVTPL (IFRS 9 / IAS 32 judgement). Issuer is principal and holds the shares on its own balance sheet. 0.5% fee on issue and redemption. T+1 settlement.
A9: Try this | B9: Change a quantity on OnChain or Journal, or the report date on Assumptions, and watch Recon and Tests react. Delete a break (for example add the missing 0xT05 entries to Journal) and confirm the checks go green.
A10: Not modelled | B10: Dividends and withholding tax, stock splits and rebasing, FX (AED/USD), custody fees, bank reconciliation, gas costs.
A11: Companion | B11: A Python version of the same model is in the same repository (tokenized_equities_ledger.py).

Sheet Assumptions
A1: Assumptions and inputs
A2: Blue = typed input. Yellow = key assumption. All prices, quantities and hashes are synthetic.
A3: Fee rate (issue and redeem) | B3: 0.005 | C3: Assumption: 0.5% fee on notional at issue and at redemption.
A4: Report date | B4: 46304 | C4: Reconciliation is run as at this date. Change it to see timing items move.
A5: Settlement cycle | B5: T+1 | C5: Hedge trades settle the next business day (WORKDAY used in Tests).
A7: Synthetic closing prices (USD per share)
A8: Date | B8: AAPL | C8: NVDA
A9: 46300 | B9: 210 | C9: 120
A10: 46301 | B10: 212 | C10: 118
A11: 46302 | B11: 211 | C11: 125
A12: 46303 | B12: 215 | C12: 127
A13: 46304 | B13: 214 | C13: 126
A15: Policy assumption (illustrative, not any real company's model): tokens are financial liabilities at FVTPL; backing shares are financial assets at FVTPL; issuer is principal and holds the shares on its own balance sheet.

Sheet COA
A1: Chart of accounts
A4: Code | B4: Account name | C4: Type
A5: 1000 | B5: Cash | C5: Asset
A6: 1100 | B6: Investments in underlying shares (FVTPL) | C6: Asset
A7: 1200 | B7: Due from broker (unsettled sales) | C7: Asset
A8: 2000 | B8: Token liability (FVTPL) | C8: Liability
A9: 2100 | B9: Due to broker (unsettled purchases) | C9: Liability
A10: 4000 | B10: Fee income | C10: Income
A11: 4100 | B11: FV gain/loss - underlying investments | C11: Income
A12: 4200 | B12: FV gain/loss - token liability | C12: Expense

Sheet OnChain
A1: On-chain events (source: blockchain explorer / issuer smart contract)
A2: One row per mint or burn. Quantities are positive; column G applies the sign.
A4: Tx hash | B4: Date | C4: Kind | D4: Ticker | E4: Qty (tokens) | F4: Wallet | G4: Signed qty
A5: 0xT01 | B5: 46300 | C5: MINT | D5: AAPL | E5: 100 | F5: walletA | G5: =IF(C5="MINT",E5,-E5) -> 100
A6: 0xT02 | B6: 46300 | C6: MINT | D6: NVDA | E6: 500 | F6: walletB | G6: =IF(C6="MINT",E6,-E6) -> 500
A7: 0xT03 | B7: 46301 | C7: MINT | D7: AAPL | E7: 50 | F7: walletC | G7: =IF(C7="MINT",E7,-E7) -> 50
A8: 0xT04 | B8: 46302 | C8: BURN | D8: AAPL | E8: 30 | F8: walletA | G8: =IF(C8="MINT",E8,-E8) -> -30
A9: 0xT05 | B9: 46302 | C9: MINT | D9: NVDA | E9: 200 | F9: walletD | G9: =IF(C9="MINT",E9,-E9) -> 200
A10: 0xT06 | B10: 46303 | C10: BURN | D10: NVDA | E10: 100 | F10: walletB | G10: =IF(C10="MINT",E10,-E10) -> -100
A11: 0xT07 | B11: 46303 | C11: MINT | D11: AAPL | E11: 40 | F11: walletE | G11: =IF(C11="MINT",E11,-E11) -> 40
A12: 0xT08 | B12: 46304 | C12: MINT | D12: NVDA | E12: 25 | F12: walletF | G12: =IF(C12="MINT",E12,-E12) -> 25
A13: 0xT09 | B13: 46304 | C13: BURN | D13: AAPL | E13: 20 | F13: walletC | G13: =IF(C13="MINT",E13,-E13) -> -20

Sheet Custodian
A1: Custodian trade confirmations (source: custodian / broker statement)
A2: Signed quantity: purchases positive, sales negative. A trade the custodian never executed has no row here.
A4: Trade ID | B4: Ticker | C4: Signed qty (shares) | D4: Trade date | E4: Settle date | F4: Status at report date
A5: HEDGE-0xT01 | B5: AAPL | C5: 100 | D5: 46300 | E5: 46301 | F5: =IF(E5<=Assumptions!$B$4,"Settled","Pending") -> Settled
A6: HEDGE-0xT02 | B6: NVDA | C6: 500 | D6: 46300 | E6: 46301 | F6: =IF(E6<=Assumptions!$B$4,"Settled","Pending") -> Settled
A7: HEDGE-0xT03 | B7: AAPL | C7: 50 | D7: 46301 | E7: 46302 | F7: =IF(E7<=Assumptions!$B$4,"Settled","Pending") -> Settled
A8: HEDGE-0xT04 | B8: AAPL | C8: -30 | D8: 46302 | E8: 46303 | F8: =IF(E8<=Assumptions!$B$4,"Settled","Pending") -> Settled
A9: HEDGE-0xT05 | B9: NVDA | C9: 200 | D9: 46302 | E9: 46303 | F9: =IF(E9<=Assumptions!$B$4,"Settled","Pending") -> Settled
A10: HEDGE-0xT06 | B10: NVDA | C10: -100 | D10: 46303 | E10: 46304 | F10: =IF(E10<=Assumptions!$B$4,"Settled","Pending") -> Settled
A11: HEDGE-0xT07 | B11: AAPL | C11: 40 | D11: 46303 | E11: 46304 | F11: =IF(E11<=Assumptions!$B$4,"Settled","Pending") -> Settled
A12: HEDGE-0xT08 | B12: NVDA | C12: 25 | D12: 46304 | E12: 46307 | F12: =IF(E12<=Assumptions!$B$4,"Settled","Pending") -> Pending
A13: HEDGE-0xT09 | B13: AAPL | C13: -20 | D13: 46304 | E13: 46307 | F13: =IF(E13<=Assumptions!$B$4,"Settled","Pending") -> Pending

Sheet Journal
A1: General ledger journal (every line is one debit or credit)
A2: Blue = typed (date, ref, account, ticker, signed qty). Black = formulas (price, notional, debits, credits). Qty is the change in tokens (acct 2000) or shares (acct 1100); revaluation lines carry 0.
A4: JE # | B4: Date | C4: Ref | D4: Memo | E4: Account | F4: Account name | G4: Ticker | H4: Signed qty | I4: Price (USD) | J4: Amount basis | K4: Debit | L4: Credit | M4: Balance check
A5: 1 | B5: 46300 | C5: 0xT01 | D5: Issue 100 AAPL tokens | E5: 1000 | F5: =INDEX(COA!$B$5:$B$12,MATCH(E5,COA!$A$5:$A$12,0)) -> Cash | J5: =J6+J7 -> 21105 | K5: =J5 -> 21105 | M5: =IF(ROUND(SUMIFS($K$5:$K$300,$A$5:$A$300,A5)-SUMIFS($L$5:$L$300,$A$5:$A$300,A5),2)=0,"OK","UNBALANCED") -> OK
A6: 1 | B6: 46300 | C6: 0xT01 | D6: Issue 100 AAPL tokens | E6: 2000 | F6: =INDEX(COA!$B$5:$B$12,MATCH(E6,COA!$A$5:$A$12,0)) -> Token liability (FVTPL) | G6: AAPL | H6: 100 | I6: =IF(G6="","",INDEX(Assumptions!$B$9:$C$13,MATCH(B6,Assumptions!$A$9:$A$13,0),MATCH(G6,Assumptions!$B$8:$C$8,0))) -> 210 | J6: =ROUND(ABS(H6)*I6,2) -> 21000 | L6: =J6 -> 21000 | M6: =IF(ROUND(SUMIFS($K$5:$K$300,$A$5:$A$300,A6)-SUMIFS($L$5:$L$300,$A$5:$A$300,A6),2)=0,"OK","UNBALANCED") -> OK
A7: 1 | B7: 46300 | C7: 0xT01 | D7: Issue 100 AAPL tokens | E7: 4000 | F7: =INDEX(COA!$B$5:$B$12,MATCH(E7,COA!$A$5:$A$12,0)) -> Fee income | J7: =ROUND(J6*Assumptions!$B$3,2) -> 105 | L7: =J7 -> 105 | M7: =IF(ROUND(SUMIFS($K$5:$K$300,$A$5:$A$300,A7)-SUMIFS($L$5:$L$300,$A$5:$A$300,A7),2)=0,"OK","UNBALANCED") -> OK
A8: 2 | B8: 46300 | C8: HEDGE-0xT01 | D8: Buy 100 AAPL to back issuance | E8: 1100 | F8: =INDEX(COA!$B$5:$B$12,MATCH(E8,COA!$A$5:$A$12,0)) -> Investments in underlying shares (FVTPL) | G8: AAPL | H8: 100 | I8: =IF(G8="","",INDEX(Assumptions!$B$9:$C$13,MATCH(B8,Assumptions!$A$9:$A$13,0),MATCH(G8,Assumptions!$B$8:$C$8,0))) -> 210 | J8: =ROUND(ABS(H8)*I8,2) -> 21000 | K8: =J8 -> 21000 | M8: =IF(ROUND(SUMIFS($K$5:$K$300,$A$5:$A$300,A8)-SUMIFS($L$5:$L$300,$A$5:$A$300,A8),2)=0,"OK","UNBALANCED") -> OK
A9: 2 | B9: 46300 | C9: HEDGE-0xT01 | D9: Buy 100 AAPL to back issuance | E9: 2100 | F9: =INDEX(COA!$B$5:$B$12,MATCH(E9,COA!$A$5:$A$12,0)) -> Due to broker (unsettled purchases) | L9: =J8 -> 21000 | M9: =IF(ROUND(SUMIFS($K$5:$K$300,$A$5:$A$300,A9)-SUMIFS($L$5:$L$300,$A$5:$A$300,A9),2)=0,"OK","UNBALANCED") -> OK
A10: 3 | B10: 46300 | C10: 0xT02 | D10: Issue 500 NVDA tokens | E10: 1000 | F10: =INDEX(COA!$B$5:$B$12,MATCH(E10,COA!$A$5:$A$12,0)) -> Cash | J10: =J11+J12 -> 60300 | K10: =J10 -> 60300 | M10: =IF(ROUND(SUMIFS($K$5:$K$300,$A$5:$A$300,A10)-SUMIFS($L$5:$L$300,$A$5:$A$300,A10),2)=0,"OK","UNBALANCED") -> OK
A11: 3 | B11: 46300 | C11: 0xT02 | D11: Issue 500 NVDA tokens | E11: 2000 | F11: =INDEX(COA!$B$5:$B$12,MATCH(E11,COA!$A$5:$A$12,0)) -> Token liability (FVTPL) | G11: NVDA | H11: 500 | I11: =IF(G11="","",INDEX(Assumptions!$B$9:$C$13,MATCH(B11,Assumptions!$A$9:$A$13,0),MATCH(G11,Assumptions!$B$8:$C$8,0))) -> 120 | J11: =ROUND(ABS(H11)*I11,2) -> 60000 | L11: =J11 -> 60000 | M11: =IF(ROUND(SUMIFS($K$5:$K$300,$A$5:$A$300,A11)-SUMIFS($L$5:$L$300,$A$5:$A$300,A11),2)=0,"OK","UNBALANCED") -> OK
A12: 3 | B12: 46300 | C12: 0xT02 | D12: Issue 500 NVDA tokens | E12: 4000 | F12: =INDEX(COA!$B$5:$B$12,MATCH(E12,COA!$A$5:$A$12,0)) -> Fee income | J12: =ROUND(J11*Assumptions!$B$3,2) -> 300 | L12: =J12 -> 300 | M12: =IF(ROUND(SUMIFS($K$5:$K$300,$A$5:$A$300,A12)-SUMIFS($L$5:$L$300,$A$5:$A$300,A12),2)=0,"OK","UNBALANCED") -> OK
A13: 4 | B13: 46300 | C13: HEDGE-0xT02 | D13: Buy 500 NVDA to back issuance | E13: 1100 | F13: =INDEX(COA!$B$5:$B$12,MATCH(E13,COA!$A$5:$A$12,0)) -> Investments in underlying shares (FVTPL) | G13: NVDA | H13: 500 | I13: =IF(G13="","",INDEX(Assumptions!$B$9:$C$13,MATCH(B13,Assumptions!$A$9:$A$13,0),MATCH(G13,Assumptions!$B$8:$C$8,0))) -> 120 | J13: =ROUND(ABS(H13)*I13,2) -> 60000 | K13: =J13 -> 60000 | M13: =IF(ROUND(SUMIFS($K$5:$K$300,$A$5:$A$300,A13)-SUMIFS($L$5:$L$300,$A$5:$A$300,A13),2)=0,"OK","UNBALANCED") -> OK
A14: 4 | B14: 46300 | C14: HEDGE-0xT02 | D14: Buy 500 NVDA to back issuance | E14: 2100 | F14: =INDEX(COA!$B$5:$B$12,MATCH(E14,COA!$A$5:$A$12,0)) -> Due to broker (unsettled purchases) | L14: =J13 -> 60000 | M14: =IF(ROUND(SUMIFS($K$5:$K$300,$A$5:$A$300,A14)-SUMIFS($L$5:$L$300,$A$5:$A$300,A14),2)=0,"OK","UNBALANCED") -> OK
A15: 5 | B15: 46301 | C15: SETTLE-HEDGE-0xT01 | D15: Settle purchase | E15: 2100 | F15: =INDEX(COA!$B$5:$B$12,MATCH(E15,COA!$A$5:$A$12,0)) -> Due to broker (unsettled purchases) | J15: =J8 -> 21000 | K15: =J15 -> 21000 | M15: =IF(ROUND(SUMIFS($K$5:$K$300,$A$5:$A$300,A15)-SUMIFS($L$5:$L$300,$A$5:$A$300,A15),2)=0,"OK","UNBALANCED") -> OK
A16: 5 | B16: 46301 | C16: SETTLE-HEDGE-0xT01 | D16: Settle purchase | E16: 1000 | F16: =INDEX(COA!$B$5:$B$12,MATCH(E16,COA!$A$5:$A$12,0)) -> Cash | L16: =J15 -> 21000 | M16: =IF(ROUND(SUMIFS($K$5:$K$300,$A$5:$A$300,A16)-SUMIFS($L$5:$L$300,$A$5:$A$300,A16),2)=0,"OK","UNBALANCED") -> OK
A17: 6 | B17: 46301 | C17: SETTLE-HEDGE-0xT02 | D17: Settle purchase | E17: 2100 | F17: =INDEX(COA!$B$5:$B$12,MATCH(E17,COA!$A$5:$A$12,0)) -> Due to broker (unsettled purchases) | J17: =J13 -> 60000 | K17: =J17 -> 60000 | M17: =IF(ROUND(SUMIFS($K$5:$K$300,$A$5:$A$300,A17)-SUMIFS($L$5:$L$300,$A$5:$A$300,A17),2)=0,"OK","UNBALANCED") -> OK
A18: 6 | B18: 46301 | C18: SETTLE-HEDGE-0xT02 | D18: Settle purchase | E18: 1000 | F18: =INDEX(COA!$B$5:$B$12,MATCH(E18,COA!$A$5:$A$12,0)) -> Cash | L18: =J17 -> 60000 | M18: =IF(ROUND(SUMIFS($K$5:$K$300,$A$5:$A$300,A18)-SUMIFS($L$5:$L$300,$A$5:$A$300,A18),2)=0,"OK","UNBALANCED") -> OK
A19: 7 | B19: 46301 | C19: REVAL-AAPL-2026-10-06 | D19: Remeasure AAPL to fair value | E19: 1100 | F19: =INDEX(COA!$B$5:$B$12,MATCH(E19,COA!$A$5:$A$12,0)) -> Investments in underlying shares (FVTPL) | G19: AAPL | H19: 0 | I19: =IF(G19="","",INDEX(Assumptions!$B$9:$C$13,MATCH(B19,Assumptions!$A$9:$A$13,0),MATCH(G19,Assumptions!$B$8:$C$8,0))) -> 212 | J19: =ROUND(SUMIFS($H$5:$H$300,$E$5:$E$300,1100,$G$5:$G$300,G19,$B$5:$B$300,"<"&B19)*(I19-INDEX(Assumptions!$B$9:$C$13,MATCH(B19,Assumptions!$A$9:$A$13,0)-1,MATCH(G19,Assumptions!$B$8:$C$8,0))),2) -> 200 | K19: =MAX(J19,0) -> 200 | L19: =MAX(-J19,0) -> 0 | M19: =IF(ROUND(SUMIFS($K$5:$K$300,$A$5:$A$300,A19)-SUMIFS($L$5:$L$300,$A$5:$A$300,A19),2)=0,"OK","UNBALANCED") -> OK
A20: 7 | B20: 46301 | C20: REVAL-AAPL-2026-10-06 | D20: Remeasure AAPL to fair value | E20: 4100 | F20: =INDEX(COA!$B$5:$B$12,MATCH(E20,COA!$A$5:$A$12,0)) -> FV gain/loss - underlying investments | J20: =J19 -> 200 | K20: =MAX(-J20,0) -> 0 | L20: =MAX(J20,0) -> 200 | M20: =IF(ROUND(SUMIFS($K$5:$K$300,$A$5:$A$300,A20)-SUMIFS($L$5:$L$300,$A$5:$A$300,A20),2)=0,"OK","UNBALANCED") -> OK
A21: 7 | B21: 46301 | C21: REVAL-AAPL-2026-10-06 | D21: Remeasure AAPL to fair value | E21: 2000 | F21: =INDEX(COA!$B$5:$B$12,MATCH(E21,COA!$A$5:$A$12,0)) -> Token liability (FVTPL) | G21: AAPL | H21: 0 | I21: =IF(G21="","",INDEX(Assumptions!$B$9:$C$13,MATCH(B21,Assumptions!$A$9:$A$13,0),MATCH(G21,Assumptions!$B$8:$C$8,0))) -> 212 | J21: =ROUND(SUMIFS($H$5:$H$300,$E$5:$E$300,2000,$G$5:$G$300,G21,$B$5:$B$300,"<"&B21)*(I21-INDEX(Assumptions!$B$9:$C$13,MATCH(B19,Assumptions!$A$9:$A$13,0)-1,MATCH(G19,Assumptions!$B$8:$C$8,0))),2) -> 200 | K21: =MAX(-J21,0) -> 0 | L21: =MAX(J21,0) -> 200 | M21: =IF(ROUND(SUMIFS($K$5:$K$300,$A$5:$A$300,A21)-SUMIFS($L$5:$L$300,$A$5:$A$300,A21),2)=0,"OK","UNBALANCED") -> OK
A22: 7 | B22: 46301 | C22: REVAL-AAPL-2026-10-06 | D22: Remeasure AAPL to fair value | E22: 4200 | F22: =INDEX(COA!$B$5:$B$12,MATCH(E22,COA!$A$5:$A$12,0)) -> FV gain/loss - token liability | J22: =J21 -> 200 | K22: =MAX(J22,0) -> 200 | L22: =MAX(-J22,0) -> 0 | M22: =IF(ROUND(SUMIFS($K$5:$K$300,$A$5:$A$300,A22)-SUMIFS($L$5:$L$300,$A$5:$A$300,A22),2)=0,"OK","UNBALANCED") -> OK
A23: 8 | B23: 46301 | C23: REVAL-NVDA-2026-10-06 | D23: Remeasure NVDA to fair value | E23: 1100 | F23: =INDEX(COA!$B$5:$B$12,MATCH(E23,COA!$A$5:$A$12,0)) -> Investments in underlying shares (FVTPL) | G23: NVDA | H23: 0 | I23: =IF(G23="","",INDEX(Assumptions!$B$9:$C$13,MATCH(B23,Assumptions!$A$9:$A$13,0),MATCH(G23,Assumptions!$B$8:$C$8,0))) -> 118 | J23: =ROUND(SUMIFS($H$5:$H$300,$E$5:$E$300,1100,$G$5:$G$300,G23,$B$5:$B$300,"<"&B23)*(I23-INDEX(Assumptions!$B$9:$C$13,MATCH(B23,Assumptions!$A$9:$A$13,0)-1,MATCH(G23,Assumptions!$B$8:$C$8,0))),2) -> -1000 | K23: =MAX(J23,0) -> 0 | L23: =MAX(-J23,0) -> 1000 | M23: =IF(ROUND(SUMIFS($K$5:$K$300,$A$5:$A$300,A23)-SUMIFS($L$5:$L$300,$A$5:$A$300,A23),2)=0,"OK","UNBALANCED") -> OK
A24: 8 | B24: 46301 | C24: REVAL-NVDA-2026-10-06 | D24: Remeasure NVDA to fair value | E24: 4100 | F24: =INDEX(COA!$B$5:$B$12,MATCH(E24,COA!$A$5:$A$12,0)) -> FV gain/loss - underlying investments | J24: =J23 -> -1000 | K24: =MAX(-J24,0) -> 1000 | L24: =MAX(J24,0) -> 0 | M24: =IF(ROUND(SUMIFS($K$5:$K$300,$A$5:$A$300,A24)-SUMIFS($L$5:$L$300,$A$5:$A$300,A24),2)=0,"OK","UNBALANCED") -> OK
A25: 8 | B25: 46301 | C25: REVAL-NVDA-2026-10-06 | D25: Remeasure NVDA to fair value | E25: 2000 | F25: =INDEX(COA!$B$5:$B$12,MATCH(E25,COA!$A$5:$A$12,0)) -> Token liability (FVTPL) | G25: NVDA | H25: 0 | I25: =IF(G25="","",INDEX(Assumptions!$B$9:$C$13,MATCH(B25,Assumptions!$A$9:$A$13,0),MATCH(G25,Assumptions!$B$8:$C$8,0))) -> 118 | J25: =ROUND(SUMIFS($H$5:$H$300,$E$5:$E$300,2000,$G$5:$G$300,G25,$B$5:$B$300,"<"&B25)*(I25-INDEX(Assumptions!$B$9:$C$13,MATCH(B23,Assumptions!$A$9:$A$13,0)-1,MATCH(G23,Assumptions!$B$8:$C$8,0))),2) -> -1000 | K25: =MAX(-J25,0) -> 1000 | L25: =MAX(J25,0) -> 0 | M25: =IF(ROUND(SUMIFS($K$5:$K$300,$A$5:$A$300,A25)-SUMIFS($L$5:$L$300,$A$5:$A$300,A25),2)=0,"OK","UNBALANCED") -> OK
A26: 8 | B26: 46301 | C26: REVAL-NVDA-2026-10-06 | D26: Remeasure NVDA to fair value | E26: 4200 | F26: =INDEX(COA!$B$5:$B$12,MATCH(E26,COA!$A$5:$A$12,0)) -> FV gain/loss - token liability | J26: =J25 -> -1000 | K26: =MAX(J26,0) -> 0 | L26: =MAX(-J26,0) -> 1000 | M26: =IF(ROUND(SUMIFS($K$5:$K$300,$A$5:$A$300,A26)-SUMIFS($L$5:$L$300,$A$5:$A$300,A26),2)=0,"OK","UNBALANCED") -> OK
A27: 9 | B27: 46301 | C27: 0xT03 | D27: Issue 50 AAPL tokens | E27: 1000 | F27: =INDEX(COA!$B$5:$B$12,MATCH(E27,COA!$A$5:$A$12,0)) -> Cash | J27: =J28+J29 -> 10653 | K27: =J27 -> 10653 | M27: =IF(ROUND(SUMIFS($K$5:$K$300,$A$5:$A$300,A27)-SUMIFS($L$5:$L$300,$A$5:$A$300,A27),2)=0,"OK","UNBALANCED") -> OK
A28: 9 | B28: 46301 | C28: 0xT03 | D28: Issue 50 AAPL tokens | E28: 2000 | F28: =INDEX(COA!$B$5:$B$12,MATCH(E28,COA!$A$5:$A$12,0)) -> Token liability (FVTPL) | G28: AAPL | H28: 50 | I28: =IF(G28="","",INDEX(Assumptions!$B$9:$C$13,MATCH(B28,Assumptions!$A$9:$A$13,0),MATCH(G28,Assumptions!$B$8:$C$8,0))) -> 212 | J28: =ROUND(ABS(H28)*I28,2) -> 10600 | L28: =J28 -> 10600 | M28: =IF(ROUND(SUMIFS($K$5:$K$300,$A$5:$A$300,A28)-SUMIFS($L$5:$L$300,$A$5:$A$300,A28),2)=0,"OK","UNBALANCED") -> OK
A29: 9 | B29: 46301 | C29: 0xT03 | D29: Issue 50 AAPL tokens | E29: 4000 | F29: =INDEX(COA!$B$5:$B$12,MATCH(E29,COA!$A$5:$A$12,0)) -> Fee income | J29: =ROUND(J28*Assumptions!$B$3,2) -> 53 | L29: =J29 -> 53 | M29: =IF(ROUND(SUMIFS($K$5:$K$300,$A$5:$A$300,A29)-SUMIFS($L$5:$L$300,$A$5:$A$300,A29),2)=0,"OK","UNBALANCED") -> OK
A30: 10 | B30: 46301 | C30: HEDGE-0xT03 | D30: Buy 50 AAPL to back issuance | E30: 1100 | F30: =INDEX(COA!$B$5:$B$12,MATCH(E30,COA!$A$5:$A$12,0)) -> Investments in underlying shares (FVTPL) | G30: AAPL | H30: 50 | I30: =IF(G30="","",INDEX(Assumptions!$B$9:$C$13,MATCH(B30,Assumptions!$A$9:$A$13,0),MATCH(G30,Assumptions!$B$8:$C$8,0))) -> 212 | J30: =ROUND(ABS(H30)*I30,2) -> 10600 | K30: =J30 -> 10600 | M30: =IF(ROUND(SUMIFS($K$5:$K$300,$A$5:$A$300,A30)-SUMIFS($L$5:$L$300,$A$5:$A$300,A30),2)=0,"OK","UNBALANCED") -> OK
A31: 10 | B31: 46301 | C31: HEDGE-0xT03 | D31: Buy 50 AAPL to back issuance | E31: 2100 | F31: =INDEX(COA!$B$5:$B$12,MATCH(E31,COA!$A$5:$A$12,0)) -> Due to broker (unsettled purchases) | L31: =J30 -> 10600 | M31: =IF(ROUND(SUMIFS($K$5:$K$300,$A$5:$A$300,A31)-SUMIFS($L$5:$L$300,$A$5:$A$300,A31),2)=0,"OK","UNBALANCED") -> OK
A32: 11 | B32: 46302 | C32: SETTLE-HEDGE-0xT03 | D32: Settle purchase | E32: 2100 | F32: =INDEX(COA!$B$5:$B$12,MATCH(E32,COA!$A$5:$A$12,0)) -> Due to broker (unsettled purchases) | J32: =J30 -> 10600 | K32: =J32 -> 10600 | M32: =IF(ROUND(SUMIFS($K$5:$K$300,$A$5:$A$300,A32)-SUMIFS($L$5:$L$300,$A$5:$A$300,A32),2)=0,"OK","UNBALANCED") -> OK
A33: 11 | B33: 46302 | C33: SETTLE-HEDGE-0xT03 | D33: Settle purchase | E33: 1000 | F33: =INDEX(COA!$B$5:$B$12,MATCH(E33,COA!$A$5:$A$12,0)) -> Cash | L33: =J32 -> 10600 | M33: =IF(ROUND(SUMIFS($K$5:$K$300,$A$5:$A$300,A33)-SUMIFS($L$5:$L$300,$A$5:$A$300,A33),2)=0,"OK","UNBALANCED") -> OK
A34: 12 | B34: 46302 | C34: REVAL-AAPL-2026-10-07 | D34: Remeasure AAPL to fair value | E34: 1100 | F34: =INDEX(COA!$B$5:$B$12,MATCH(E34,COA!$A$5:$A$12,0)) -> Investments in underlying shares (FVTPL) | G34: AAPL | H34: 0 | I34: =IF(G34="","",INDEX(Assumptions!$B$9:$C$13,MATCH(B34,Assumptions!$A$9:$A$13,0),MATCH(G34,Assumptions!$B$8:$C$8,0))) -> 211 | J34: =ROUND(SUMIFS($H$5:$H$300,$E$5:$E$300,1100,$G$5:$G$300,G34,$B$5:$B$300,"<"&B34)*(I34-INDEX(Assumptions!$B$9:$C$13,MATCH(B34,Assumptions!$A$9:$A$13,0)-1,MATCH(G34,Assumptions!$B$8:$C$8,0))),2) -> -150 | K34: =MAX(J34,0) -> 0 | L34: =MAX(-J34,0) -> 150 | M34: =IF(ROUND(SUMIFS($K$5:$K$300,$A$5:$A$300,A34)-SUMIFS($L$5:$L$300,$A$5:$A$300,A34),2)=0,"OK","UNBALANCED") -> OK
A35: 12 | B35: 46302 | C35: REVAL-AAPL-2026-10-07 | D35: Remeasure AAPL to fair value | E35: 4100 | F35: =INDEX(COA!$B$5:$B$12,MATCH(E35,COA!$A$5:$A$12,0)) -> FV gain/loss - underlying investments | J35: =J34 -> -150 | K35: =MAX(-J35,0) -> 150 | L35: =MAX(J35,0) -> 0 | M35: =IF(ROUND(SUMIFS($K$5:$K$300,$A$5:$A$300,A35)-SUMIFS($L$5:$L$300,$A$5:$A$300,A35),2)=0,"OK","UNBALANCED") -> OK
A36: 12 | B36: 46302 | C36: REVAL-AAPL-2026-10-07 | D36: Remeasure AAPL to fair value | E36: 2000 | F36: =INDEX(COA!$B$5:$B$12,MATCH(E36,COA!$A$5:$A$12,0)) -> Token liability (FVTPL) | G36: AAPL | H36: 0 | I36: =IF(G36="","",INDEX(Assumptions!$B$9:$C$13,MATCH(B36,Assumptions!$A$9:$A$13,0),MATCH(G36,Assumptions!$B$8:$C$8,0))) -> 211 | J36: =ROUND(SUMIFS($H$5:$H$300,$E$5:$E$300,2000,$G$5:$G$300,G36,$B$5:$B$300,"<"&B36)*(I36-INDEX(Assumptions!$B$9:$C$13,MATCH(B34,Assumptions!$A$9:$A$13,0)-1,MATCH(G34,Assumptions!$B$8:$C$8,0))),2) -> -150 | K36: =MAX(-J36,0) -> 150 | L36: =MAX(J36,0) -> 0 | M36: =IF(ROUND(SUMIFS($K$5:$K$300,$A$5:$A$300,A36)-SUMIFS($L$5:$L$300,$A$5:$A$300,A36),2)=0,"OK","UNBALANCED") -> OK
A37: 12 | B37: 46302 | C37: REVAL-AAPL-2026-10-07 | D37: Remeasure AAPL to fair value | E37: 4200 | F37: =INDEX(COA!$B$5:$B$12,MATCH(E37,COA!$A$5:$A$12,0)) -> FV gain/loss - token liability | J37: =J36 -> -150 | K37: =MAX(J37,0) -> 0 | L37: =MAX(-J37,0) -> 150 | M37: =IF(ROUND(SUMIFS($K$5:$K$300,$A$5:$A$300,A37)-SUMIFS($L$5:$L$300,$A$5:$A$300,A37),2)=0,"OK","UNBALANCED") -> OK
A38: 13 | B38: 46302 | C38: REVAL-NVDA-2026-10-07 | D38: Remeasure NVDA to fair value | E38: 1100 | F38: =INDEX(COA!$B$5:$B$12,MATCH(E38,COA!$A$5:$A$12,0)) -> Investments in underlying shares (FVTPL) | G38: NVDA | H38: 0 | I38: =IF(G38="","",INDEX(Assumptions!$B$9:$C$13,MATCH(B38,Assumptions!$A$9:$A$13,0),MATCH(G38,Assumptions!$B$8:$C$8,0))) -> 125 | J38: =ROUND(SUMIFS($H$5:$H$300,$E$5:$E$300,1100,$G$5:$G$300,G38,$B$5:$B$300,"<"&B38)*(I38-INDEX(Assumptions!$B$9:$C$13,MATCH(B38,Assumptions!$A$9:$A$13,0)-1,MATCH(G38,Assumptions!$B$8:$C$8,0))),2) -> 3500 | K38: =MAX(J38,0) -> 3500 | L38: =MAX(-J38,0) -> 0 | M38: =IF(ROUND(SUMIFS($K$5:$K$300,$A$5:$A$300,A38)-SUMIFS($L$5:$L$300,$A$5:$A$300,A38),2)=0,"OK","UNBALANCED") -> OK
A39: 13 | B39: 46302 | C39: REVAL-NVDA-2026-10-07 | D39: Remeasure NVDA to fair value | E39: 4100 | F39: =INDEX(COA!$B$5:$B$12,MATCH(E39,COA!$A$5:$A$12,0)) -> FV gain/loss - underlying investments | J39: =J38 -> 3500 | K39: =MAX(-J39,0) -> 0 | L39: =MAX(J39,0) -> 3500 | M39: =IF(ROUND(SUMIFS($K$5:$K$300,$A$5:$A$300,A39)-SUMIFS($L$5:$L$300,$A$5:$A$300,A39),2)=0,"OK","UNBALANCED") -> OK
A40: 13 | B40: 46302 | C40: REVAL-NVDA-2026-10-07 | D40: Remeasure NVDA to fair value | E40: 2000 | F40: =INDEX(COA!$B$5:$B$12,MATCH(E40,COA!$A$5:$A$12,0)) -> Token liability (FVTPL) | G40: NVDA | H40: 0 | I40: =IF(G40="","",INDEX(Assumptions!$B$9:$C$13,MATCH(B40,Assumptions!$A$9:$A$13,0),MATCH(G40,Assumptions!$B$8:$C$8,0))) -> 125 | J40: =ROUND(SUMIFS($H$5:$H$300,$E$5:$E$300,2000,$G$5:$G$300,G40,$B$5:$B$300,"<"&B40)*(I40-INDEX(Assumptions!$B$9:$C$13,MATCH(B38,Assumptions!$A$9:$A$13,0)-1,MATCH(G38,Assumptions!$B$8:$C$8,0))),2) -> 3500 | K40: =MAX(-J40,0) -> 0 | L40: =MAX(J40,0) -> 3500 | M40: =IF(ROUND(SUMIFS($K$5:$K$300,$A$5:$A$300,A40)-SUMIFS($L$5:$L$300,$A$5:$A$300,A40),2)=0,"OK","UNBALANCED") -> OK
A41: 13 | B41: 46302 | C41: REVAL-NVDA-2026-10-07 | D41: Remeasure NVDA to fair value | E41: 4200 | F41: =INDEX(COA!$B$5:$B$12,MATCH(E41,COA!$A$5:$A$12,0)) -> FV gain/loss - token liability | J41: =J40 -> 3500 | K41: =MAX(J41,0) -> 3500 | L41: =MAX(-J41,0) -> 0 | M41: =IF(ROUND(SUMIFS($K$5:$K$300,$A$5:$A$300,A41)-SUMIFS($L$5:$L$300,$A$5:$A$300,A41),2)=0,"OK","UNBALANCED") -> OK
...

Sheet TrialBalance
A1: Trial balance
A4: Account | B4: Name | C4: Total debits | D4: Total credits | E4: Debit balance | F4: Credit balance
A5: =COA!A5 -> 1000 | B5: =COA!B5 -> Cash | C5: =SUMIFS(Journal!$K$5:$K$300,Journal!$E$5:$E$300,A5) -> 148021.75 | D5: =SUMIFS(Journal!$L$5:$L$300,Journal!$E$5:$E$300,A5) -> 148393.45 | E5: =MAX(C5-D5,0) -> 0 | F5: =MAX(D5-C5,0) -> 371.7
A6: =COA!A6 -> 1100 | B6: =COA!B6 -> Investments in underlying shares (FVTPL) | C6: =SUMIFS(Journal!$K$5:$K$300,Journal!$E$5:$E$300,A6) -> 133930 | D6: =SUMIFS(Journal!$L$5:$L$300,Journal!$E$5:$E$300,A6) -> 25220 | E6: =MAX(C6-D6,0) -> 108710 | F6: =MAX(D6-C6,0) -> 0
A7: =COA!A7 -> 1200 | B7: =COA!B7 -> Due from broker (unsettled sales) | C7: =SUMIFS(Journal!$K$5:$K$300,Journal!$E$5:$E$300,A7) -> 23310 | D7: =SUMIFS(Journal!$L$5:$L$300,Journal!$E$5:$E$300,A7) -> 19030 | E7: =MAX(C7-D7,0) -> 4280 | F7: =MAX(D7-C7,0) -> 0
A8: =COA!A8 -> 2000 | B8: =COA!B8 -> Token liability (FVTPL) | C8: =SUMIFS(Journal!$K$5:$K$300,Journal!$E$5:$E$300,A8) -> 25220 | D8: =SUMIFS(Journal!$L$5:$L$300,Journal!$E$5:$E$300,A8) -> 133930 | E8: =MAX(C8-D8,0) -> 0 | F8: =MAX(D8-C8,0) -> 108710
A9: =COA!A9 -> 2100 | B9: =COA!B9 -> Due to broker (unsettled purchases) | C9: =SUMIFS(Journal!$K$5:$K$300,Journal!$E$5:$E$300,A9) -> 125200 | D9: =SUMIFS(Journal!$L$5:$L$300,Journal!$E$5:$E$300,A9) -> 128350 | E9: =MAX(C9-D9,0) -> 0 | F9: =MAX(D9-C9,0) -> 3150
A10: =COA!A10 -> 4000 | B10: =COA!B10 -> Fee income | C10: =SUMIFS(Journal!$K$5:$K$300,Journal!$E$5:$E$300,A10) -> 0 | D10: =SUMIFS(Journal!$L$5:$L$300,Journal!$E$5:$E$300,A10) -> 758.3 | E10: =MAX(C10-D10,0) -> 0 | F10: =MAX(D10-C10,0) -> 758.3
A11: =COA!A11 -> 4100 | B11: =COA!B11 -> FV gain/loss - underlying investments | C11: =SUMIFS(Journal!$K$5:$K$300,Journal!$E$5:$E$300,A11) -> 1910 | D11: =SUMIFS(Journal!$L$5:$L$300,Journal!$E$5:$E$300,A11) -> 5580 | E11: =MAX(C11-D11,0) -> 0 | F11: =MAX(D11-C11,0) -> 3670
A12: =COA!A12 -> 4200 | B12: =COA!B12 -> FV gain/loss - token liability | C12: =SUMIFS(Journal!$K$5:$K$300,Journal!$E$5:$E$300,A12) -> 5580 | D12: =SUMIFS(Journal!$L$5:$L$300,Journal!$E$5:$E$300,A12) -> 1910 | E12: =MAX(C12-D12,0) -> 3670 | F12: =MAX(D12-C12,0) -> 0
B13: Total | C13: =SUM(C5:C12) -> 463171.75 | D13: =SUM(D5:D12) -> 463171.75 | E13: =SUM(E5:E12) -> 116660 | F13: =SUM(F5:F12) -> 116660
A15: Trial balance check (debits - credits) | E15: =ROUND(E13-F13,2) -> 0 | F15: =IF(E15=0,"OK","OUT OF BALANCE") -> OK
A16: Unbalanced journal entries (count) | E16: =COUNTIF(Journal!$M$5:$M$300,"UNBALANCED") -> 0 | F16: =IF(E16=0,"OK","INVESTIGATE") -> OK
A17: Net fair-value result (gain on shares less loss on token liability) | E17: =(D11-C11)-(C12-D12) -> 0 | F17: =IF(E17=0,"OK","BOOKS DO NOT MATCH") -> OK
A18: Net FV result should be zero while the token book and the share book hold the same units. A non-zero value is P&L noise caused by a unit break (see Recon, check R4).

Sheet Recon
A1: Three-way unit reconciliation: on-chain vs ledger vs custodian
A2: Report date: | B2: =Assumptions!$B$4 -> 46304
A4: Ticker | B4: On-chain supply (tokens) | C4: Ledger tokens (acct 2000) | D4: Ledger shares (acct 1100) | E4: Custodian settled | F4: Custodian pending (T+1) | G4: Custodian trade-date position | H4: R1 on-chain less ledger tokens | I4: R2 ledger shares less custodian | J4: R3 on-chain less custodian (backing gap) | K4: R4 ledger tokens less ledger shares | L4: Status
A5: AAPL | B5: =SUMIFS(OnChain!$G$5:$G$100,OnChain!$D$5:$D$100,A5) -> 140 | C5: =SUMIFS(Journal!$H$5:$H$300,Journal!$E$5:$E$300,2000,Journal!$G$5:$G$300,A5) -> 140 | D5: =SUMIFS(Journal!$H$5:$H$300,Journal!$E$5:$E$300,1100,Journal!$G$5:$G$300,A5) -> 140 | E5: =SUMIFS(Custodian!$C$5:$C$100,Custodian!$B$5:$B$100,A5,Custodian!$E$5:$E$100,"<="&Assumptions!$B$4) -> 160 | F5: =G5-E5 -> -20 | G5: =SUMIFS(Custodian!$C$5:$C$100,Custodian!$B$5:$B$100,A5) -> 140 | H5: =B5-C5 -> 0 | I5: =D5-G5 -> 0 | J5: =B5-G5 -> 0 | K5: =C5-D5 -> 0 | L5: =IF(AND(H5=0,I5=0,J5=0,K5=0),"OK","BREAK") -> OK
A6: NVDA | B6: =SUMIFS(OnChain!$G$5:$G$100,OnChain!$D$5:$D$100,A6) -> 625 | C6: =SUMIFS(Journal!$H$5:$H$300,Journal!$E$5:$E$300,2000,Journal!$G$5:$G$300,A6) -> 625 | D6: =SUMIFS(Journal!$H$5:$H$300,Journal!$E$5:$E$300,1100,Journal!$G$5:$G$300,A6) -> 625 | E6: =SUMIFS(Custodian!$C$5:$C$100,Custodian!$B$5:$B$100,A6,Custodian!$E$5:$E$100,"<="&Assumptions!$B$4) -> 600 | F6: =G6-E6 -> 25 | G6: =SUMIFS(Custodian!$C$5:$C$100,Custodian!$B$5:$B$100,A6) -> 625 | H6: =B6-C6 -> 0 | I6: =D6-G6 -> 0 | J6: =B6-G6 -> 0 | K6: =C6-D6 -> 0 | L6: =IF(AND(H6=0,I6=0,J6=0,K6=0),"OK","BREAK") -> OK
A9: How to read this tab
A10: Custodian pending is a legitimate timing difference (trades done, not yet settled). Columns R1 to R4 are not allowed to be non-zero.
A11: R1: tokens in circulation vs the ledger's token liability units. Non-zero means a missed or mis-keyed posting.
A12: R2: shares the ledger says we hold vs what the custodian confirms on a trade-date basis. Non-zero means a hedge trade is missing or was never executed.
A13: R3: tokens in circulation vs shares actually held at the custodian. A positive number means tokens are not fully backed (the most serious break).
A14: R4: the ledger's token units vs the ledger's own share units. Non-zero means the books disagree internally and the P&L picks up noise.
A15: Netting hides errors: one NVDA break offsets part of another in R1, which is why the transaction-level tests on the Tests tab matter.

Sheet Tests
A1: Transaction-level tests
A3: A. Token entries: completeness (T1) and accuracy (T3), one row per on-chain event
A4: Tx hash | B4: Kind | C4: Ticker | D4: On-chain qty | E4: Ledger token lines | F4: Ledger token qty | G4: Difference | H4: Result
A5: =OnChain!A5 -> 0xT01 | B5: =OnChain!C5 -> MINT | C5: =OnChain!D5 -> AAPL | D5: =OnChain!E5 -> 100 | E5: =COUNTIFS(Journal!$C$5:$C$300,A5,Journal!$E$5:$E$300,2000) -> 1 | F5: =ABS(SUMIFS(Journal!$H$5:$H$300,Journal!$C$5:$C$300,A5,Journal!$E$5:$E$300,2000)) -> 100 | G5: =D5-F5 -> 0 | H5: =IF(E5=0,"MISSING IN LEDGER (completeness)",IF(G5<>0,"QTY MISMATCH (accuracy)","OK")) -> OK
A6: =OnChain!A6 -> 0xT02 | B6: =OnChain!C6 -> MINT | C6: =OnChain!D6 -> NVDA | D6: =OnChain!E6 -> 500 | E6: =COUNTIFS(Journal!$C$5:$C$300,A6,Journal!$E$5:$E$300,2000) -> 1 | F6: =ABS(SUMIFS(Journal!$H$5:$H$300,Journal!$C$5:$C$300,A6,Journal!$E$5:$E$300,2000)) -> 500 | G6: =D6-F6 -> 0 | H6: =IF(E6=0,"MISSING IN LEDGER (completeness)",IF(G6<>0,"QTY MISMATCH (accuracy)","OK")) -> OK
A7: =OnChain!A7 -> 0xT03 | B7: =OnChain!C7 -> MINT | C7: =OnChain!D7 -> AAPL | D7: =OnChain!E7 -> 50 | E7: =COUNTIFS(Journal!$C$5:$C$300,A7,Journal!$E$5:$E$300,2000) -> 1 | F7: =ABS(SUMIFS(Journal!$H$5:$H$300,Journal!$C$5:$C$300,A7,Journal!$E$5:$E$300,2000)) -> 50 | G7: =D7-F7 -> 0 | H7: =IF(E7=0,"MISSING IN LEDGER (completeness)",IF(G7<>0,"QTY MISMATCH (accuracy)","OK")) -> OK
A8: =OnChain!A8 -> 0xT04 | B8: =OnChain!C8 -> BURN | C8: =OnChain!D8 -> AAPL | D8: =OnChain!E8 -> 30 | E8: =COUNTIFS(Journal!$C$5:$C$300,A8,Journal!$E$5:$E$300,2000) -> 1 | F8: =ABS(SUMIFS(Journal!$H$5:$H$300,Journal!$C$5:$C$300,A8,Journal!$E$5:$E$300,2000)) -> 30 | G8: =D8-F8 -> 0 | H8: =IF(E8=0,"MISSING IN LEDGER (completeness)",IF(G8<>0,"QTY MISMATCH (accuracy)","OK")) -> OK
A9: =OnChain!A9 -> 0xT05 | B9: =OnChain!C9 -> MINT | C9: =OnChain!D9 -> NVDA | D9: =OnChain!E9 -> 200 | E9: =COUNTIFS(Journal!$C$5:$C$300,A9,Journal!$E$5:$E$300,2000) -> 1 | F9: =ABS(SUMIFS(Journal!$H$5:$H$300,Journal!$C$5:$C$300,A9,Journal!$E$5:$E$300,2000)) -> 200 | G9: =D9-F9 -> 0 | H9: =IF(E9=0,"MISSING IN LEDGER (completeness)",IF(G9<>0,"QTY MISMATCH (accuracy)","OK")) -> OK
A10: =OnChain!A10 -> 0xT06 | B10: =OnChain!C10 -> BURN | C10: =OnChain!D10 -> NVDA | D10: =OnChain!E10 -> 100 | E10: =COUNTIFS(Journal!$C$5:$C$300,A10,Journal!$E$5:$E$300,2000) -> 2 | F10: =ABS(SUMIFS(Journal!$H$5:$H$300,Journal!$C$5:$C$300,A10,Journal!$E$5:$E$300,2000)) -> 100 | G10: =D10-F10 -> 0 | H10: =IF(E10=0,"MISSING IN LEDGER (completeness)",IF(G10<>0,"QTY MISMATCH (accuracy)","OK")) -> OK
A11: =OnChain!A11 -> 0xT07 | B11: =OnChain!C11 -> MINT | C11: =OnChain!D11 -> AAPL | D11: =OnChain!E11 -> 40 | E11: =COUNTIFS(Journal!$C$5:$C$300,A11,Journal!$E$5:$E$300,2000) -> 1 | F11: =ABS(SUMIFS(Journal!$H$5:$H$300,Journal!$C$5:$C$300,A11,Journal!$E$5:$E$300,2000)) -> 40 | G11: =D11-F11 -> 0 | H11: =IF(E11=0,"MISSING IN LEDGER (completeness)",IF(G11<>0,"QTY MISMATCH (accuracy)","OK")) -> OK
A12: =OnChain!A12 -> 0xT08 | B12: =OnChain!C12 -> MINT | C12: =OnChain!D12 -> NVDA | D12: =OnChain!E12 -> 25 | E12: =COUNTIFS(Journal!$C$5:$C$300,A12,Journal!$E$5:$E$300,2000) -> 1 | F12: =ABS(SUMIFS(Journal!$H$5:$H$300,Journal!$C$5:$C$300,A12,Journal!$E$5:$E$300,2000)) -> 25 | G12: =D12-F12 -> 0 | H12: =IF(E12=0,"MISSING IN LEDGER (completeness)",IF(G12<>0,"QTY MISMATCH (accuracy)","OK")) -> OK
A13: =OnChain!A13 -> 0xT09 | B13: =OnChain!C13 -> BURN | C13: =OnChain!D13 -> AAPL | D13: =OnChain!E13 -> 20 | E13: =COUNTIFS(Journal!$C$5:$C$300,A13,Journal!$E$5:$E$300,2000) -> 1 | F13: =ABS(SUMIFS(Journal!$H$5:$H$300,Journal!$C$5:$C$300,A13,Journal!$E$5:$E$300,2000)) -> 20 | G13: =D13-F13 -> 0 | H13: =IF(E13=0,"MISSING IN LEDGER (completeness)",IF(G13<>0,"QTY MISMATCH (accuracy)","OK")) -> OK
A16: B. Hedge trades: ledger vs custodian, and settlement ageing (T4, T5)
A17: Tx hash | B17: Hedge trade ID | C17: Trade date | D17: Settle date (T+1) | E17: Custodian qty | F17: Ledger shares qty | G17: Difference | H17: Settlement posted? | I17: Result
A18: =OnChain!A5 -> 0xT01 | B18: ="HEDGE-"&A18 -> HEDGE-0xT01 | C18: =OnChain!B5 -> 46300 | D18: =WORKDAY(C18,1) -> 46301 | E18: =SUMIFS(Custodian!$C$5:$C$100,Custodian!$A$5:$A$100,B18) -> 100 | F18: =SUMIFS(Journal!$H$5:$H$300,Journal!$C$5:$C$300,B18,Journal!$E$5:$E$300,1100) -> 100 | G18: =F18-E18 -> 0 | H18: =IF(COUNTIF(Journal!$C$5:$C$300,"SETTLE-"&B18)>0,"Yes","No") -> Yes | I18: =IF(AND(E18=0,F18<>0),"LEDGER TRADE NOT CONFIRMED BY CUSTODIAN",IF(AND(E18<>0,F18=0),"CUSTODIAN TRADE NOT IN LEDGER",IF(E18<>F18,"QTY MISMATCH",IF(D18>Assumptions!$B$4,"PENDING (timing)",IF(H18="No","UNSETTLED PAST DUE","OK"))))) -> OK
A19: =OnChain!A6 -> 0xT02 | B19: ="HEDGE-"&A19 -> HEDGE-0xT02 | C19: =OnChain!B6 -> 46300 | D19: =WORKDAY(C19,1) -> 46301 | E19: =SUMIFS(Custodian!$C$5:$C$100,Custodian!$A$5:$A$100,B19) -> 500 | F19: =SUMIFS(Journal!$H$5:$H$300,Journal!$C$5:$C$300,B19,Journal!$E$5:$E$300,1100) -> 500 | G19: =F19-E19 -> 0 | H19: =IF(COUNTIF(Journal!$C$5:$C$300,"SETTLE-"&B19)>0,"Yes","No") -> Yes | I19: =IF(AND(E19=0,F19<>0),"LEDGER TRADE NOT CONFIRMED BY CUSTODIAN",IF(AND(E19<>0,F19=0),"CUSTODIAN TRADE NOT IN LEDGER",IF(E19<>F19,"QTY MISMATCH",IF(D19>Assumptions!$B$4,"PENDING (timing)",IF(H19="No","UNSETTLED PAST DUE","OK"))))) -> OK
A20: =OnChain!A7 -> 0xT03 | B20: ="HEDGE-"&A20 -> HEDGE-0xT03 | C20: =OnChain!B7 -> 46301 | D20: =WORKDAY(C20,1) -> 46302 | E20: =SUMIFS(Custodian!$C$5:$C$100,Custodian!$A$5:$A$100,B20) -> 50 | F20: =SUMIFS(Journal!$H$5:$H$300,Journal!$C$5:$C$300,B20,Journal!$E$5:$E$300,1100) -> 50 | G20: =F20-E20 -> 0 | H20: =IF(COUNTIF(Journal!$C$5:$C$300,"SETTLE-"&B20)>0,"Yes","No") -> Yes | I20: =IF(AND(E20=0,F20<>0),"LEDGER TRADE NOT CONFIRMED BY CUSTODIAN",IF(AND(E20<>0,F20=0),"CUSTODIAN TRADE NOT IN LEDGER",IF(E20<>F20,"QTY MISMATCH",IF(D20>Assumptions!$B$4,"PENDING (timing)",IF(H20="No","UNSETTLED PAST DUE","OK"))))) -> OK
A21: =OnChain!A8 -> 0xT04 | B21: ="HEDGE-"&A21 -> HEDGE-0xT04 | C21: =OnChain!B8 -> 46302 | D21: =WORKDAY(C21,1) -> 46303 | E21: =SUMIFS(Custodian!$C$5:$C$100,Custodian!$A$5:$A$100,B21) -> -30 | F21: =SUMIFS(Journal!$H$5:$H$300,Journal!$C$5:$C$300,B21,Journal!$E$5:$E$300,1100) -> -30 | G21: =F21-E21 -> 0 | H21: =IF(COUNTIF(Journal!$C$5:$C$300,"SETTLE-"&B21)>0,"Yes","No") -> Yes | I21: =IF(AND(E21=0,F21<>0),"LEDGER TRADE NOT CONFIRMED BY CUSTODIAN",IF(AND(E21<>0,F21=0),"CUSTODIAN TRADE NOT IN LEDGER",IF(E21<>F21,"QTY MISMATCH",IF(D21>Assumptions!$B$4,"PENDING (timing)",IF(H21="No","UNSETTLED PAST DUE","OK"))))) -> OK
A22: =OnChain!A9 -> 0xT05 | B22: ="HEDGE-"&A22 -> HEDGE-0xT05 | C22: =OnChain!B9 -> 46302 | D22: =WORKDAY(C22,1) -> 46303 | E22: =SUMIFS(Custodian!$C$5:$C$100,Custodian!$A$5:$A$100,B22) -> 200 | F22: =SUMIFS(Journal!$H$5:$H$300,Journal!$C$5:$C$300,B22,Journal!$E$5:$E$300,1100) -> 200 | G22: =F22-E22 -> 0 | H22: =IF(COUNTIF(Journal!$C$5:$C$300,"SETTLE-"&B22)>0,"Yes","No") -> Yes | I22: =IF(AND(E22=0,F22<>0),"LEDGER TRADE NOT CONFIRMED BY CUSTODIAN",IF(AND(E22<>0,F22=0),"CUSTODIAN TRADE NOT IN LEDGER",IF(E22<>F22,"QTY MISMATCH",IF(D22>Assumptions!$B$4,"PENDING (timing)",IF(H22="No","UNSETTLED PAST DUE","OK"))))) -> OK
A23: =OnChain!A10 -> 0xT06 | B23: ="HEDGE-"&A23 -> HEDGE-0xT06 | C23: =OnChain!B10 -> 46303 | D23: =WORKDAY(C23,1) -> 46304 | E23: =SUMIFS(Custodian!$C$5:$C$100,Custodian!$A$5:$A$100,B23) -> -100 | F23: =SUMIFS(Journal!$H$5:$H$300,Journal!$C$5:$C$300,B23,Journal!$E$5:$E$300,1100) -> -100 | G23: =F23-E23 -> 0 | H23: =IF(COUNTIF(Journal!$C$5:$C$300,"SETTLE-"&B23)>0,"Yes","No") -> Yes | I23: =IF(AND(E23=0,F23<>0),"LEDGER TRADE NOT CONFIRMED BY CUSTODIAN",IF(AND(E23<>0,F23=0),"CUSTODIAN TRADE NOT IN LEDGER",IF(E23<>F23,"QTY MISMATCH",IF(D23>Assumptions!$B$4,"PENDING (timing)",IF(H23="No","UNSETTLED PAST DUE","OK"))))) -> OK
A24: =OnChain!A11 -> 0xT07 | B24: ="HEDGE-"&A24 -> HEDGE-0xT07 | C24: =OnChain!B11 -> 46303 | D24: =WORKDAY(C24,1) -> 46304 | E24: =SUMIFS(Custodian!$C$5:$C$100,Custodian!$A$5:$A$100,B24) -> 40 | F24: =SUMIFS(Journal!$H$5:$H$300,Journal!$C$5:$C$300,B24,Journal!$E$5:$E$300,1100) -> 40 | G24: =F24-E24 -> 0 | H24: =IF(COUNTIF(Journal!$C$5:$C$300,"SETTLE-"&B24)>0,"Yes","No") -> Yes | I24: =IF(AND(E24=0,F24<>0),"LEDGER TRADE NOT CONFIRMED BY CUSTODIAN",IF(AND(E24<>0,F24=0),"CUSTODIAN TRADE NOT IN LEDGER",IF(E24<>F24,"QTY MISMATCH",IF(D24>Assumptions!$B$4,"PENDING (timing)",IF(H24="No","UNSETTLED PAST DUE","OK"))))) -> OK
A25: =OnChain!A12 -> 0xT08 | B25: ="HEDGE-"&A25 -> HEDGE-0xT08 | C25: =OnChain!B12 -> 46304 | D25: =WORKDAY(C25,1) -> 46307 | E25: =SUMIFS(Custodian!$C$5:$C$100,Custodian!$A$5:$A$100,B25) -> 25 | F25: =SUMIFS(Journal!$H$5:$H$300,Journal!$C$5:$C$300,B25,Journal!$E$5:$E$300,1100) -> 25 | G25: =F25-E25 -> 0 | H25: =IF(COUNTIF(Journal!$C$5:$C$300,"SETTLE-"&B25)>0,"Yes","No") -> No | I25: =IF(AND(E25=0,F25<>0),"LEDGER TRADE NOT CONFIRMED BY CUSTODIAN",IF(AND(E25<>0,F25=0),"CUSTODIAN TRADE NOT IN LEDGER",IF(E25<>F25,"QTY MISMATCH",IF(D25>Assumptions!$B$4,"PENDING (timing)",IF(H25="No","UNSETTLED PAST DUE","OK"))))) -> PENDING (timing)
A26: =OnChain!A13 -> 0xT09 | B26: ="HEDGE-"&A26 -> HEDGE-0xT09 | C26: =OnChain!B13 -> 46304 | D26: =WORKDAY(C26,1) -> 46307 | E26: =SUMIFS(Custodian!$C$5:$C$100,Custodian!$A$5:$A$100,B26) -> -20 | F26: =SUMIFS(Journal!$H$5:$H$300,Journal!$C$5:$C$300,B26,Journal!$E$5:$E$300,1100) -> -20 | G26: =F26-E26 -> 0 | H26: =IF(COUNTIF(Journal!$C$5:$C$300,"SETTLE-"&B26)>0,"Yes","No") -> No | I26: =IF(AND(E26=0,F26<>0),"LEDGER TRADE NOT CONFIRMED BY CUSTODIAN",IF(AND(E26<>0,F26=0),"CUSTODIAN TRADE NOT IN LEDGER",IF(E26<>F26,"QTY MISMATCH",IF(D26>Assumptions!$B$4,"PENDING (timing)",IF(H26="No","UNSETTLED PAST DUE","OK"))))) -> PENDING (timing)
A29: C. Existence (T2): ledger entries that reference an on-chain hash that does not exist
A30: Count of such entries (expected 0) | F30: =SUMPRODUCT((LEFT(Journal!$C$5:$C$300,2)="0x")*(COUNTIF(OnChain!$A$5:$A$100,Journal!$C$5:$C$300)=0)) -> 0 | G30: =IF(F30=0,"OK","INVESTIGATE") -> OK
A32: Summary of exceptions
A33: Section A exceptions | F33: =COUNTIF(H5:H13,"<>OK") -> 0
A34: Section B exceptions (excluding timing items) | F34: =COUNTIF(I18:I26,"<>OK")-COUNTIF(I18:I26,"PENDING*") -> 0
A35: Section B pending (timing, not an exception) | F35: =COUNTIF(I18:I26,"PENDING*") -> 2

Sheet Findings
A1: Injected breaks and what catches them
A2: Commentary only. The scenario is synthetic; each break mirrors a real control failure type.
A4: # | B4: What was injected | C4: Where it shows up | D4: Control that catches it | E4: Likely root cause | F4: Suggested fix
A5: 1 | B5: 0xT05: 200 NVDA tokens minted on-chain and bought at the custodian, but never posted in the ledger. | C5: Tests A (MISSING IN LEDGER), Tests B (CUSTODIAN TRADE NOT IN LEDGER), Recon R1 and R2 for NVDA. | D5: Completeness test: every on-chain event must have a journal entry. | E5: Posting feed from the issuance system dropped an event. | F5: Post the missing issuance and hedge entries; add an automated on-chain-to-ledger completeness check each day.
A6: 2 | B6: 0xT06: a 100-token NVDA redemption keyed as 10 tokens in the ledger. | C6: Tests A (QTY MISMATCH), Recon R1 and R4 for NVDA, and a non-zero net FV result on TrialBalance. | D6: Accuracy test: ledger token quantity must equal on-chain quantity. | E6: Manual keying error or truncation in the integration. | F6: Correct the entry; remove manual keying for token events and post straight from the on-chain feed.
A7: 3 | B7: 0xT07: 40 AAPL tokens minted and booked, but the custodian never executed the hedge buy. | C7: Tests B (LEDGER TRADE NOT CONFIRMED BY CUSTODIAN), Recon R2 and R3 for AAPL (backing gap). | D7: Custodian confirmation match and the on-chain-to-custodian backing check. | E7: Hedge order rejected or never sent; ledger booked on instruction, not on confirmation. | F7: Escalate immediately: tokens are not fully backed. Re-execute the trade, and book only on custodian confirmation.
A8: 4 | B8: Why the totals can hide errors | C8: Recon R1 for NVDA is the net of break 1 and break 2. | D8: Transaction-level tests on the Tests tab. | E8: Offsetting errors net down in a unit total. | F8: Never rely on totals alone; test completeness and accuracy per transaction.
